Workbook

Sheet README
A1: Klaris — Structure de coûts détaillée
A2: Une marque Next Move · v1.0 · 15 mai 2026 · Confidentiel
A4: Objet | B4: Modèle de coûts couvrant la livraison de la roadmap Klaris sur 18 mois. Trois scénarios alignés sur les jalons commerciaux : Now (10 courtiers, pré-amorçage), Next (200 courtiers, Seed), Later (1 000 courtiers, prép. Series A). Tous les montants en $CAD sauf indication contraire.
A5: Méthodologie | B5: Bottom-up par outil. Hypothèses volumétriques explicites (Sheet README §Hypothèses). Sensibilité +/-20% sur leviers clés (Sheet Sensitivity).
A6: Devise | B6: $CAD. Conversion appliquée : 1 USD = 1,36 CAD (mai 2026, moyenne 90 j).
A8: Hypothèses volumétriques
A9: Conversations SMS / courtier / mois | B9: ~150 (5 leads/j × 30 j ; 30% qualifiés)
A10: Messages Twilio sortants / courtier / mois | B10: ~450 (3 par conversation moy.)
A11: Tokens Anthropic / courtier / mois (qualif) | B11: ~120 k input + ~30 k output
A12: Tokens Anthropic / courtier / mois (briefing+RAG) | B12: ~80 k input + ~20 k output
A13: Mémos vocaux transcrits / courtier / mois | B13: ~40 (~30 min audio total)
A14: Embeddings / courtier / mois (RAG V1) | B14: ~500 chunks × 1536 dims
A15: Embeddings / agence / mois (RAG V2 listings) | B15: ~5 000 listings réindexés / 7 j
A16: Offres rédigées / courtier / mois (Sprint 8) | B16: ~3 (50% pilotes)
A17: Signatures Notarius / courtier / mois | B17: ~4 (1 offre = ~2 signataires)
A18: Storage Supabase / courtier | B18: ~150 MB (mémos compressés + PDF)
A19: Bandwidth dashboard / courtier / mois | B19: ~2 GB
A20: Crash-free rate cible | B20: ≥ 99% (Sentry plan ajusté)
A22: Scénarios — courtiers actifs
A23: Now (T+0 à T+3) | B23: 10 courtiers · pré-amorçage 250 k$ · MRR 1 000 $
A24: Next (T+4 à T+9) | B24: 200 courtiers · Seed 1,5 M$ · MRR 25 000 $
A25: Later (T+10 à T+18) | B25: 1 000 courtiers · prép. Series A · MRR 125 000 $
A27: Légende couleurs
A28: Now (10 courtiers)
A29: Next (200 courtiers)
A30: Later (1 000 courtiers)
A32: Avertissement
A33: Modèle d'intention — pas un budget engagé. Les prix outils peuvent varier (promotions, négociations enterprise). Toutes les estimations sont à valider auprès des fournisseurs au moment du déploiement.

Sheet Outils & Infra
A1: Catalogue outils & infrastructure
A2: Tous coûts $CAD/mois sauf indication. Colonnes Now/Next/Later = total $/mois à ce volume.
A4: Catégorie | B4: Outil | C4: Plan / SKU | D4: Unité | E4: Coût unitaire $CAD | F4: Now (10c) | G4: Next (200c) | H4: Later (1000c) | I4: Notes
A5: A. IA & ML
A6: A. IA & ML | B6: Anthropic Claude Sonnet 4.6 | C6: API usage-based | D6: $/M tokens (in 3$ / out 15$) | E6: var | F6: 65 | G6: 1300 | H6: 7000 | I6: Qualification + briefing. ~150k tokens/courtier/mois.
A7: A. IA & ML | B7: Anthropic Claude Haiku 4.5 | C7: API usage-based | D7: $/M tokens (in 1$ / out 5$) | E7: var | F7: 8 | G7: 150 | H7: 750 | I7: Résumés mémos + suggestions courtes.
A8: A. IA & ML | B8: Anthropic Prompt Caching | C8: 5-min TTL | D8: −90% input tokens cached | E8: var | F8: -8 | G8: -160 | H8: -900 | I8: Économie via cache prompts système Klaris.
A9: A. IA & ML | B9: OpenAI Whisper API | C9: whisper-1 | D9: $/min audio (0,006 USD) | E9: 0,008 | F9: 12 | G9: 245 | H9: 1230 | I9: Transcription mémos vocaux + voicemails.
A10: A. IA & ML | B10: OpenAI Embeddings (RAG V1) | C10: text-embedding-3-small | D10: $/M tokens (0,02 USD) | E10: 0,027 | F10: 3 | G10: 54 | H10: 270 | I10: Indexation knowledge base agence.
A11: A. IA & ML | B11: Voyage AI Embeddings (Next) | C11: voyage-3 | D11: $/M tokens (0,06 USD) | E11: 0,082 | F11: 0 | G11: 35 | H11: 180 | I11: Upgrade RAG V2 — précision +15% vs OpenAI.
A12: A. IA & ML | B12: Voyage AI Rerank (Next) | C12: rerank-2 | D12: $/M tokens (0,05 USD) | E12: 0,068 | F12: 0 | G12: 22 | H12: 110 | I12: Reranking RAG V2.
A13: A. IA & ML | B13: Mistral La Plateforme | C13: mistral-large | D13: fallback (10% trafic Next) | E13: var | F13: 0 | G13: 45 | H13: 220 | I13: Fallback Anthropic — résilience + cost arb.
A14: A. IA & ML | B14: Cohere Rerank (alternative) | C14: rerank-3 | D14: alternative Voyage | E14: 0 | F14: 0 | G14: 0 | H14: 0 | I14: En réserve si Voyage indispo.
A15: A. IA & ML | B15: Upstash Redis (cache RAG) | C15: Pay-as-you-go | D15: $/req + storage | E15: var | F15: 0 | G15: 35 | H15: 150 | I15: Cache sémantique embeddings — RAG V4.
A16: B. Infra prod
A17: B. Infra prod | B17: Supabase | C17: Pro $25 + usage | D17: $/projet/mois | E17: 25 | F17: 25 | G17: 125 | H17: 500 | I17: Pro Now ; Team @ Next (egress + concurrent); Enterprise Later.
A18: B. Infra prod | B18: Supabase Storage | C18: $0,021/GB | D18: $/GB/mois | E18: 0,021 | F18: 1 | G18: 12 | H18: 55 | I18: Mémos + PDF offres + briefings.
A19: B. Infra prod | B19: Supabase egress | C19: $0,09/GB | D19: $/GB/mois | E19: 0,09 | F19: 2 | G19: 45 | H19: 220 | I19: Dashboard + iOS sync.
A20: B. Infra prod | B20: Twilio numéro local QC | C20: $1,50 USD/numéro | D20: $/numéro/mois | E20: 2,04 | F20: 20 | G20: 410 | H20: 2040 | I20: 1 numéro / courtier.
A21: B. Infra prod | B21: Twilio SMS sortants | C21: $0,0075 USD/SMS | D21: $/SMS | E21: 0,010 | F21: 45 | G21: 900 | H21: 4500 | I21: ~450 SMS sortants/courtier/mois.
A22: B. Infra prod | B22: Twilio SMS entrants | C22: $0,0075 USD/SMS | D22: $/SMS | E22: 0,010 | F22: 15 | G22: 300 | H22: 1500 | I22: ~150 entrants.
A23: B. Infra prod | B23: n8n hosting (Railway) | C23: Pro $20 | D23: $/mois | E23: 27 | F23: 27 | G23: 27 | H23: 0 | I23: Self-hosted. Migré service Python @ Later.
A24: B. Infra prod | B24: Service Python (Later) | C24: Cloud Run + GCS | D24: $/mois | E24: var | F24: 0 | G24: 0 | H24: 1200 | I24: Remplace n8n quand >500 courtiers.
A25: B. Infra prod | B25: Vercel Pro | C25: klaris.app web | D25: $/seat/mois | E25: 27 | F25: 54 | G25: 81 | H25: 108 | I25: 2 → 3 → 4 seats.
A26: B. Infra prod | B26: Sentry Team | C26: Team $26 + events | D26: $/mois | E26: 35 | F26: 35 | G26: 85 | H26: 290 | I26: Errors + perf monitoring iOS+web.
A27: B. Infra prod | B27: Logflare | C27: Logging | D27: $/mois | E27: 34 | F27: 34 | G27: 34 | H27: 150 | I27: Logs n8n → Postgres → BigQuery.
A28: B. Infra prod | B28: Browserless.io | C28: PDF rendering | D28: $/mois | E28: 68 | F28: 68 | G28: 68 | H28: 150 | I28: Rapports PDF mensuels courtier.
... A33: B. Infra prod | B33: BrowserStack | C33: Live $39 USD | D33: $/seat/mois | E33: 53 | F33: 53 | G33: 53 | H33: 106 | I33: Tests cross-device iOS.
A34: C. Outils dev
A35: C. Outils dev | B35: Claude Code (Pro) | C35: 20$/seat/mois | D35: $/seat | E35: 27 | F35: 54 | G35: 108 | H35: 270 | I35: Cofondateurs Now ; +contractors Next/Later.
A36: C. Outils dev | B36: Cursor Pro | C36: $20 USD/seat | D36: $/seat | E36: 27 | F36: 54 | G36: 108 | H36: 270 | I36: IDE IA — alternative ou complément Claude Code.
A37: C. Outils dev | B37: GitHub Copilot Business | C37: $19 USD/seat | D37: $/seat | E37: 26 | F37: 52 | G37: 104 | H37: 260 | I37: Co-coding mobile + backend.
A38: C. Outils dev | B38: GitHub Team | C38: $4 USD/seat | D38: $/seat | E38: 5 | F38: 20 | G38: 45 | H38: 120 | I38: Private repos + actions minutes.
A39: C. Outils dev | B39: Cluely | C39: $20 USD/seat | D39: $/seat | E39: 27 | F39: 54 | G39: 108 | H39: 270 | I39: Meeting assistant — calls courtiers + démos.
A40: C. Outils dev | B40: Superwhisper | C40: $8.49 USD/seat | D40: $/seat | E40: 12 | F40: 24 | G40: 48 | H40: 120 | I40: Dictation IA — productivité notes/comms.
A41: C. Outils dev | B41: Linear Standard | C41: $10 USD/seat | D41: $/seat | E41: 14 | F41: 28 | G41: 70 | H41: 210 | I41: Tickets + roadmap (alternative Jira).
A42: C. Outils dev | B42: Jira Standard (option) | C42: $8.15 USD/seat | D42: $/seat | E42: 11 | F42: 0 | G42: 0 | H42: 330 | I42: Si franchise impose ; sinon Linear.
A43: C. Outils dev | B43: Figma Professional | C43: $15 USD/editor | D43: $/seat | E43: 20 | F43: 40 | G43: 80 | H43: 240 | I43: Design system + handoff dev.
A44: C. Outils dev | B44: Notion Plus | C44: $10 USD/seat | D44: $/seat | E44: 14 | F44: 28 | G44: 70 | H44: 210 | I44: Docs internes + base de connaissance.
A45: C. Outils dev | B45: Slack Pro | C45: $8.75 USD/seat | D45: $/seat | E45: 12 | F45: 24 | G45: 60 | H45: 180 | I45: Comms interne.
...

Sheet COGS variable
A1: COGS variable par courtier
A2: Coûts directement attribuables à un courtier. Sert à calculer la marge brute par seat.
A4: Composant | B4: Coût/courtier Now | C4: Coût/courtier Next | D4: Coût/courtier Later | E4: Source/Hypothèse | F4: Notes optimisation
A5: Anthropic Claude (Sonnet + Haiku, qualif + briefing) | B5: 7.3 | C5: 7.25 | D5: 7.75 | E5: 150k tokens/courtier/mois | F5: Prompt caching −90% Now ; négocié enterprise Later
A6: Anthropic prompt cache économie | B6: -0.8 | C6: -0.8 | D6: -0.9 | E6: 5-min TTL cache hit ~60% | F6: —
A7: OpenAI Whisper (transcription mémos) | B7: 1.22 | C7: 1.22 | D7: 1.23 | E7: 30 min audio/courtier/mois | F7: Whisper local (Faster-Whisper) Later
A8: OpenAI Embeddings (RAG) | B8: 0.3 | C8: 0.27 | D8: 0.27 | E8: 500 chunks/courtier × 1536 dims | F8: Cache embeddings agences Next
A9: Voyage Embeddings + Rerank (Next+) | B9: 0 | C9: 0.29 | D9: 0.29 | E9: RAG V2 upgrade | F9: Choisi quand precision@3 baseline plafonne
A10: Twilio SMS volume (entrant + sortant) | B10: 6 | C10: 6 | D10: 6 | E10: 600 SMS × 0,01$ | F10: Négocier volume @ 500 courtiers
A11: Twilio numéro local | B11: 2.04 | C11: 2.04 | D11: 2.04 | E11: 1 numéro/courtier | F11: Mutualisation par agence (Later)
A12: Supabase quota part (Pro plan / # courtiers) | B12: 2.5 | C12: 0.63 | D12: 0.5 | E12: $25 → $125 → $500 / N courtiers | F12: Économies d'échelle
A13: Supabase storage + egress | B13: 0.3 | C13: 0.29 | D13: 0.28 | E13: 150 MB + 2 GB egress / courtier | F13: CDN klaris.app Cloudflare
A14: Sentry quota part | B14: 3.5 | C14: 0.43 | D14: 0.29 | E14: Plan team | F14: —
A15: Logflare + Browserless quota part | B15: 10.2 | C15: 0.51 | D15: 0.3 | E15: Coûts fixes / N | F15: —
A16: Notarius signatures (50% adoption) | B16: 2.7 | C16: 3.4 | D16: 3.4 | E16: 4 sig/courtier/mois × 50% × 3,40$ | F16: Volume → tarif négocié
... A18: Stripe fees (% MRR) | B18: 2.9 | C18: 2.9 | D18: 3.63 | E18: 2,9% × 100$ ou 200$ MRR | F18: —
A20: TOTAL COGS / courtier / mois | B20: =SUM(B5:B18) | C20: =SUM(C5:C18) | D20: =SUM(D5:D18)
A22: Pricing Klaris (CAD/courtier/mois) | B22: 100 | C22: 100 | D22: 150 | E22: Solo Now ; Solo+Agence mix Next ; Mix +EN-CA Later
A23: Marge brute / courtier | B23: =B22 - B20 | C23: =C22 - C20 | D23: =D22 - D20
A24: Marge brute % | B24: =B23 / B22 | C24: =C23 / C22 | D24: =D23 / D22

Sheet Salaires & talent
A1: Salaires & contractors
A2: Montants $CAD/mois. Cofondateurs : équity-led Now, salaires progressifs Next+.
A4: Rôle | B4: Personne / Profil | C4: Statut | D4: Now | E4: Next | F4: Later | G4: Notes
A5: CEO / Produit | B5: Eliot | C5: Cofondateur | D5: 2000 | E5: 6000 | F5: 10000 | G5: Salaire faible Now (equity), market Next
A6: CTO / Tech lead | B6: Dennis | C6: Cofondateur | D6: 2000 | E6: 7000 | F6: 12000 | G6: Tech lead, recrute équipe Next+
A7: COO / Ventes | B7: Walkens | C7: Cofondateur | D7: 2000 | E7: 6000 | F7: 10000 | G7: Ventes courtiers, agences Next+
A8: Growth / Ops | B8: Seydou | C8: Cofondateur | D8: 2000 | E8: 5500 | F8: 9000 | G8: Onboarding pilotes Now
A9: Dev iOS Flutter | B9: Contractor | C9: Freelance | D9: 0 | E9: 8000 | F9: 10000 | G9: Sprint 7-8 Next ; emb. salarié Later
A10: Dev backend / RAG | B10: Contractor | C10: Freelance | D10: 0 | E10: 7500 | F10: 10500 | G10: RAG V2/V3 Next ; salarié Later
A11: Designer produit | B11: Contractor | C11: Freelance | D11: 0 | E11: 4000 | F11: 7500 | G11: Mi-temps Next ; full Later
A12: Customer success | B12: Junior | C12: Salarié | D12: 0 | E12: 4500 | F12: 6000 | G12: Onboarding agences Next+
A13: Sales rep agence | B13: Junior | C13: Salarié | D13: 0 | E13: 0 | F13: 6500 | G13: Couverture ON/QC Later
A14: Compliance officer | B14: Contractor | C14: Mi-temps | D14: 0 | E14: 2000 | F14: 4500 | G14: Loi 25 + OACIQ + SOC 2
A15: Stagiaire(s) | B15: Étudiants | C15: Stage | D15: 1000 | E15: 2000 | F15: 3000 | G15: Tech ou design
A16: Charges sociales (~15%) | B16: — | C16: Provision | D16: 900 | E16: 6900 | F16: 11700 | G16: CNESST + RRQ + AE
A18: TOTAL MASSE SALARIALE / MOIS | D18: =SUM(D5:D16) | E18: =SUM(E5:E16) | F18: =SUM(F5:F16)

Sheet Scénarios
A1: Scénarios consolidés — P&L mensuel
A2: Synthèse mensuelle par horizon. Liens dynamiques vers les autres feuilles.
A4: Ligne | B4: Now (10c) | C4: Next (200c) | D4: Later (1000c) | E4: Note
A5: Courtiers actifs | B5: 10 | C5: 200 | D5: 1000 | E5: Cible MRR roadmap produit
A6: ARPU mensuel ($CAD) | B6: 100 | C6: 125 | D6: 150 | E6: Mix Solo 100 $ / Agence 200 $ / EN-CA 150 $
A7: Revenus mensuels | B7: =B5*B6 | C7: =C5*C6 | D7: =D5*D6 | E7: MRR cible roadmap = 1k / 25k / 125k
A9: COGS variable / courtier | B9: ='COGS variable'!B20 | C9: ='COGS variable'!C20 | D9: ='COGS variable'!D20 | E9: Lien dynamique vers feuille COGS variable
A10: COGS total mensuel | B10: =B5*B9 | C10: =C5*C9 | D10: =D5*D9
A11: Marge brute | B11: =B7-B10 | C11: =C7-C10 | D11: =D7-D10
A12: Marge brute % | B12: =B11/B7 | C12: =C11/C7 | D12: =D11/D7
A14: OpEx — Outils & infra (hors COGS variable) | B14: ='Outils & Infra'!F84 | C14: ='Outils & Infra'!G84 | D14: ='Outils & Infra'!H84 | E14: Inclut tout : IA, infra, dev tools, compliance, marketing, admin
A15: (dont déjà compté en COGS variable) | B15: =-B10 | C15: =-C10 | D15: =-D10 | E15: Ajustement pour éviter double comptage
A16: OpEx infra nette (charges fixes) | B16: =B14+B15 | C16: =C14+C15 | D16: =D14+D15
A17: Masse salariale | B17: ='Salaires & talent'!D18 | C17: ='Salaires & talent'!E18 | D17: ='Salaires & talent'!F18 | E17: Cofondateurs + contractors + charges sociales
A18: OpEx total | B18: =B16+B17 | C18: =C16+C17 | D18: =D16+D17
A20: EBITDA mensuel | B20: =B11-B18 | C20: =C11-C18 | D20: =D11-D18 | E20: Marge brute − OpEx total
A21: EBITDA mensuel % | B21: =B20/B7 | C21: =C20/C7 | D21: =D20/D7
A22: Cash burn mensuel (si EBITDA < 0) | B22: =IF(B20<0,-B20,0) | C22: =IF(C20<0,-C20,0) | D22: =IF(D20<0,-D20,0)
A23: Cash levé cumulé ($CAD) | B23: 250000 | C23: 1750000 | D23: 1750000 | E23: Pré-amorçage 250k → +Seed 1,5M cumulé
A24: Runway (mois si burn constant) | B24: =IF(B22>0,B23/B22,"∞") | C24: =IF(C22>0,C23/C22,"∞") | D24: =IF(D22>0,D23/D22,"∞")
A26: Revenus annualisés (×12) | B26: =B7*12 | C26: =C7*12 | D26: =D7*12 | E26: ARR cible
A27: OpEx annualisée (×12) | B27: =B18*12 | C27: =C18*12 | D27: =D18*12

Sheet Sensitivity
A1: Analyse de sensibilité — leviers clés
A2: Variation ±20% sur les leviers principaux, impact EBITDA mensuel scénario Next (200 courtiers).
A4: Levier | B4: -20% | C4: -10% | D4: Baseline | E4: +10% | F4: +20%
A5: ARPU (prix Klaris) | B5: =-(0.2*Scénarios!C7) | C5: =-(0.1*Scénarios!C7) | D5: 0 | E5: =0.1*Scénarios!C7 | F5: =0.2*Scénarios!C7
A6: Coût Anthropic tokens | B6: =0.2*Scénarios!C5*'COGS variable'!C5 | C6: =0.1*Scénarios!C5*'COGS variable'!C5 | D6: 0 | E6: =-0.1*Scénarios!C5*'COGS variable'!C5 | F6: =-0.2*Scénarios!C5*'COGS variable'!C5
A7: Volume SMS Twilio | B7: =0.2*Scénarios!C5*'COGS variable'!C10 | C7: =0.1*Scénarios!C5*'COGS variable'!C10 | D7: 0 | E7: =-0.1*Scénarios!C5*'COGS variable'!C10 | F7: =-0.2*Scénarios!C5*'COGS variable'!C10
A8: Masse salariale | B8: =0.2*Scénarios!C17 | C8: =0.1*Scénarios!C17 | D8: 0 | E8: =-0.1*Scénarios!C17 | F8: =-0.2*Scénarios!C17
A9: Acquisition courtiers (vol) | B9: =-0.2*Scénarios!C7 | C9: =-0.1*Scénarios!C7 | D9: 0 | E9: =0.1*Scénarios!C7 | F9: =0.2*Scénarios!C7
A10: OpEx fixe (outils, marketing) | B10: =0.2*Scénarios!C16 | C10: =0.1*Scénarios!C16 | D10: 0 | E10: =-0.1*Scénarios!C16 | F10: =-0.2*Scénarios!C16
A12: Lecture
A13: Chiffres = impact additif sur l'EBITDA mensuel Next (baseline scénario Next colonne C de la feuille Scénarios).
A14: Conclusion : ARPU et volume d'acquisition dominent — un courtier additionnel rapporte ~110 $/mois marge directe.

Sheet Unit Economics
A1: Unit Economics — LTV / CAC / Payback
A2: Métriques par courtier acquis. Cible : LTV/CAC > 3, payback < 12 mois (benchmark SaaS B2B SMB).
A4: Métrique | B4: Now (10c) | C4: Next (200c) | D4: Later (1000c) | E4: Formule / hypothèse
A5: ARPU mensuel ($CAD) | B5: 100 | C5: 125 | D5: 150 | E5: Mix Solo / Agence / EN-CA
A6: Marge brute / courtier / mois | B6: =Scénarios!B6-'COGS variable'!B20 | C6: =Scénarios!C6-'COGS variable'!C20 | D6: =Scénarios!D6-'COGS variable'!D20 | E6: ='COGS variable'!B23 — lien dynamique
A7: Marge brute % | B7: =B6/B5 | C7: =C6/C5 | D7: =D6/D5 | E7: ='COGS variable'!B24
A8: Churn mensuel (% courtiers/mois) | B8: 0.05 | C8: 0.03 | D8: 0.02 | E8: 5% Now (early pilots) → 2% Later (sticky agences)
A9: Lifetime moyen (mois) | B9: =1/B8 | C9: =1/C8 | D9: =1/D8 | E9: =1 / churn mensuel
A10: LTV brute ($CAD) | B10: =B5*B9 | C10: =C5*C9 | D10: =D5*D9 | E10: =ARPU × Lifetime
A11: LTV marge brute ($CAD) | B11: =B6*B9 | C11: =C6*C9 | D11: =D6*D9 | E11: =Marge brute mensuelle × Lifetime
A13: Coût marketing mensuel ($CAD) | B13: 800 | C13: 5000 | D13: 14500 | E13: Google + Meta + salons + freelance + Customer.io
A14: Coût sales mensuel ($CAD) | B14: 2000 | C14: 6000 | D14: 12500 | E14: Cofondateurs Now ; +rep Next ; +rep ON Later
A15: CAC mensuel total ($CAD) | B15: =B13+B14 | C15: =C13+C14 | D15: =D13+D14 | E15: =Mkt + Sales
A16: Nouveaux courtiers acquis / mois | B16: 3 | C16: 15 | D16: 40 | E16: Taux d'acquisition net (gross − churn)
A17: CAC par courtier ($CAD) | B17: =B15/B16 | C17: =C15/C16 | D17: =D15/D16 | E17: =CAC mensuel / acquisitions
A19: LTV / CAC | B19: =B11/B17 | C19: =C11/C17 | D19: =D11/D17 | E19: Cible > 3
A20: Payback CAC (mois) | B20: =B17/B6 | C20: =C17/C6 | D20: =D17/D6 | E20: =CAC / Marge brute mensuelle
A21: Magic Number (efficience) | B21: =(B16*12*B5)/(B15*3) | C21: =(C16*12*C5)/(C15*3) | D21: =(D16*12*D5)/(D15*3) | E21: =(ΔMRR × 4) / S&M dépense trimestrielle. Cible > 0,75
A24: Benchmarks SaaS B2B SMB (référence)
A25: LTV / CAC sain | B25: > 3 (visé). > 5 = scaling robuste.
A26: Payback CAC | B26: < 12 mois early, < 18 mois growth.
A27: Churn mensuel toléré | B27: < 3% PME, < 1% entreprise.
A28: Magic Number | B28: > 0,75 (efficient). > 1 = double S&M maintenant.

Sheet Funding schedule
A1: Calendrier de financement — 18 mois
A2: Encaissements (levées + revenus) vs décaissements mensuels. Cash position cumulée. Tous montants $CAD.
A4: Mois | B4: Phase | C4: Courtiers | D4: Revenus | E4: OpEx | F4: Cash levé | G4: Burn net | H4: Note
A5: T+0 (Juin 2026) | B5: Now | C5: 10 | D5: 1000 | E5: 15000 | F5: 250000 | G5: 236000 | H5: Pré-amorçage closed · TestFlight launch
A6: T+1 | B6: Now | C6: 15 | D6: 1500 | E6: 16000 | G6: -14500 | H6: Captation OACIQ revue
A7: T+2 | B7: Now | C7: 25 | D7: 2500 | E7: 18000 | G7: -15500 | H7: App Store live · acquisition courtier
A8: T+3 (Sept) | B8: Now→Next | C8: 40 | D8: 4000 | E8: 22000 | G8: -18000 | H8: Premier deal agence pilote
A9: T+4 | B9: Next | C9: 60 | D9: 6300 | E9: 30000 | G9: -23700 | H9: Centris API négo + Notarius signé
A10: T+5 | B10: Next | C10: 90 | D10: 9450 | E10: 40000 | G10: -30550 | H10: Pré-Seed roadshow
A11: T+6 (Déc 2026) | B11: Next | C11: 130 | D11: 13650 | E11: 55000 | F11: 1500000 | G11: 1458650 | H11: Seed 1,5 M$ closed
A12: T+7 | B12: Next | C12: 165 | D12: 17325 | E12: 65000 | G12: -47675 | H12: Recrutements dev + sales
A13: T+8 (Févr 2027) | B13: Next | C13: 200 | D13: 23000 | E13: 75000 | G13: -52000 | H13: Cible Next atteinte · 200 courtiers
A14: T+9 | B14: Next→Later | C14: 250 | D14: 28750 | E14: 85000 | G14: -56250 | H14: Toronto launch préparé
A15: T+10 (Avr 2027) | B15: Later | C15: 320 | D15: 36800 | E15: 100000 | G15: -63200 | H15: Toronto + Ottawa go-live
A16: T+11 | B16: Later | C16: 400 | D16: 46000 | E16: 110000 | G16: -64000 | H16: Mid-market 1ʳᵉ vente 50+ courtiers
A17: T+12 | B17: Later | C17: 500 | D17: 65000 | E17: 115000 | G17: -50000 | H17: Cible Later début · 500 courtiers · MRR 60k
A18: T+13 (Juil 2027) | B18: Later | C18: 600 | D18: 78000 | E18: 125000 | G18: -47000 | H18: Sprint 8 GA — rédac offres OACIQ
A19: T+14 | B19: Later | C19: 700 | D19: 91000 | E19: 130000 | G19: -39000 | H19: Notarius + DocuSign GA
A20: T+15 | B20: Later | C20: 800 | D20: 116000 | E20: 135000 | G20: -19000 | H20: Marge > 75% · platform API beta
A21: T+16 (Oct 2027) | B21: Later | C21: 900 | D21: 130500 | E21: 140000 | G21: -9500 | H21: Conversations Series A (term sheet)
A22: T+17 (Nov 2027) | B22: Later | C22: 1000 | D22: 145000 | E22: 140000 | G22: 5000 | H22: Cible Later atteinte · ARR 1,5M$
A24: Cash position cumulée (fin de période)
A25: Cash début T+0 | G25: 0
A26: T+0 (Juin 2026) | G26: =G25+G5
A27: T+1 | G27: =G26+G6
A28: T+2 | G28: =G27+G7
A29: T+3 (Sept) | G29: =G28+G8
A30: T+4 | G30: =G29+G9
A31: T+5 | G31: =G30+G10
A32: T+6 (Déc 2026) | G32: =G31+G11
A33: T+7 | G33: =G32+G12
A34: T+8 (Févr 2027) | G34: =G33+G13
A35: T+9 | G35: =G34+G14
A36: T+10 (Avr 2027) | G36: =G35+G15
A37: T+11 | G37: =G36+G16
... A43: T+17 (Nov 2027) | G43: =G42+G22
A45: Total levée 18 mois | F45: =SUM(F5:F22) | H45: Pré-amorçage 250 k$ + Seed 1,5 M$ = 1,75 M$

Sheet Setup one-shot
A1: Coûts ponctuels de lancement (one-shot, hors mensuel)
A2: Investissements non récurrents — incorporation, propriété intellectuelle, hardware, dépôts initiaux.
A4: Poste | B4: Catégorie | C4: Montant $CAD | D4: Notes
A5: Incorporation fédérale + QC | B5: Légal | C5: 500 | D5: Frais gouvernementaux Industrie Canada + RBQ
A6: Convention d'actionnaires | B6: Légal | C6: 2500 | D6: Vesting cofondateurs, drag/tag along, ROFR
A7: Marque déposée 'Klaris' CA + US | B7: PI | C7: 3500 | D7: OPIC Canada + USPTO USA (2 classes)
A8: Marque 'Next Move' | B8: PI | C8: 1500 | D8: OPIC Canada classe 9 + 42
A9: Politique conf. + DPIA Loi 25 init. | B9: Conformité | C9: 3000 | D9: Rédaction initiale par DPO externe
A10: Adhésion OACIQ (revue conformité) | B10: Conformité | C10: 2500 | D10: Audit initial + lettre absence d'objection
A11: Pen-test initial | B11: Sécurité | C11: 8000 | D11: Pré-Seed — boîte spécialisée Mtl
A12: Audit sécurité Supabase config | B12: Sécurité | C12: 1500 | D12: Revue RLS + secrets management
A13: 4× MacBook Pro M4 (cofondateurs) | B13: Hardware | C13: 14000 | D13: 16'' M4 Pro 24 Go / 1 To
A14: 3× écrans 4K 27'' | B14: Hardware | C14: 1800 | D14: Workstation cofondateurs tech
A15: Mobiliers + ergonomie | B15: Hardware | C15: 3000 | D15: Chaises, bureaux, casques
A16: 4× iPhone 16 Pro (tests + démos) | B16: Hardware | C16: 6000 | D16: Test app + démos courtiers
... A25: Provision contingence | B25: Réserve | C25: 5000 | D25: Imprévus (5–10% du total)
A27: TOTAL SETUP ONE-SHOT | C27: =SUM(C5:C25)
A29: Sous-totaux par catégorie
A30: Légal | C30: =SUMIF(B5:B25,"Légal",C5:C25)
A31: PI | C31: =SUMIF(B5:B25,"PI",C5:C25)
A32: Conformité | C32: =SUMIF(B5:B25,"Conformité",C5:C25)
A33: Sécurité | C33: =SUMIF(B5:B25,"Sécurité",C5:C25)
A34: Hardware | C34: =SUMIF(B5:B25,"Hardware",C5:C25)
A35: Marketing | C35: =SUMIF(B5:B25,"Marketing",C5:C25)
A36: Acquisition | C36: =SUMIF(B5:B25,"Acquisition",C5:C25)
A37: Admin | C37: =SUMIF(B5:B25,"Admin",C5:C25)
A38: Réserve | C38: =SUMIF(B5:B25,"Réserve",C5:C25)
